Workbook
Name aa: Overview!$E$8:$E$10

Sheet Overview
A1: Product Specification Calculation v1.09 (20200130)
A2: IC Type | C2: 321
A4: CHIP0 | E4: CHIP1 | I4: CHIP2 | M4: CHIP3
A5: Display 0 (fb0~fb2) | B5: Enable | C5: 1
B6: Display Format | C6: 1.5
B7: Liveview Type | C7: 2
B8: Video width | C8: 1920
B9: Video height | C9: 1080
B10: GUI width (fb1) | C10: 1024
B11: GUI height(fb1) | C11: 768
A12: Display 1 (fb3~fb5) | B12: Enable | C12: 1
B13: Video width | C13: 720
B14: Video height | C14: 576
A15: Display 2 (fb6~fb8) | B15: Enable | C15: 0
B16: Video width | C16: 720
B17: Video height | C17: 576
A18: Decode 1 | B18: Channels | C18: 4 | E18: Decode 1 | F18: Channels | G18: 8 | I18: Decode 1 | J18: Channels | K18: 4 | M18: Decode 1 | N18: Channels | O18: 4
B19: Video width | C19: 1920 | F19: Video width | G19: 1920 | J19: Video width | K19: 1920 | N19: Video width | O19: 1920
B20: Video height | C20: 1080 | F20: Video height | G20: 1088 | J20: Video height | K20: 1088 | N20: Video height | O20: 1088
B21: YUV Buf Count | C21: 4 | F21: YUV Buf Count | G21: 4 | J21: YUV Buf Count | K21: 4 | N21: YUV Buf Count | O21: 4
A22: Decode 2 | B22: Channels | C22: 0 | E22: Decode 2 | F22: Channels | G22: 0 | I22: Decode 2 | J22: Channels | K22: 0 | M22: Decode 2 | N22: Channels | O22: 0
B23: Video width | C23: 2560 | F23: Video width | G23: 2560 | J23: Video width | K23: 2560 | N23: Video width | O23: 2560
B24: Video height | C24: 1440 | F24: Video height | G24: 1440 | J24: Video height | K24: 1440 | N24: Video height | O24: 1440
B25: YUV Buf Count | C25: 4 | F25: YUV Buf Count | G25: 4 | J25: YUV Buf Count | K25: 4 | N25: YUV Buf Count | O25: 4
A26: Main Encode 1 | B26: Channels | C26: 2 | E26: Main Encode 1 | F26: Channels | G26: 8 | I26: Main Encode 1 | J26: Channels | K26: 4 | M26: Main Encode 1 | N26: Channels | O26: 4
B27: Video width | C27: 1920 | F27: Video width | G27: 1920 | J27: Video width | K27: 1920 | N27: Video width | O27: 1920
B28: Video height | C28: 1080 | F28: Video height | G28: 1080 | J28: Video height | K28: 1080 | N28: Video height | O28: 1080
B29: YUV Buf Count | C29: 2 | F29: YUV Buf Count | G29: 2 | J29: YUV Buf Count | K29: 4 | N29: YUV Buf Count | O29: 4
A30: Main Encode 2 | B30: Channels | C30: 0 | E30: Main Encode 2 | F30: Channels | G30: 0 | I30: Main Encode 2 | J30: Channels | K30: 0 | M30: Main Encode 2 | N30: Channels | O30: 0
B31: Video width | C31: 2560 | F31: Video width | G31: 2560 | J31: Video width | K31: 2560 | N31: Video width | O31: 2560
B32: Video height | C32: 1440 | F32: Video height | G32: 1440 | J32: Video height | K32: 1440 | N32: Video height | O32: 1440
B33: YUV Buf count | C33: 2 | F33: YUV Buf count | G33: 2 | J33: YUV Buf count | K33: 2 | N33: YUV Buf count | O33: 2
A34: Substream Encode | B34: Channels | C34: 2 | E34: Sub Encode | F34: Channels | G34: 8 | I34: Sub Encode | J34: Channels | K34: 4 | M34: Sub Encode | N34: Channels | O34: 4
B35: Video width | C35: 960 | F35: Video width | G35: 960 | J35: Video width | K35: 960 | N35: Video width | O35: 960
B36: Video height | C36: 576 | F36: Video height | G36: 576 | J36: Video height | K36: 576 | N36: Video height | O36: 576
B37: YUV Buf count | C37: 2 | F37: YUV Buf count | G37: 2 | J37: YUV Buf count | K37: 4 | N37: YUV Buf count | O37: 4
A38: Encode Scaler | B38: Channels | C38: 0 | E38: Encode Scaler | F38: Channels | G38: 0 | I38: Encode Scaler | J38: Channels | K38: 0 | M38: Encode Scaler | N38: Channels | O38: 0
B39: Video width | C39: 720 | F39: Video width | G39: 720 | J39: Video width | K39: 720 | N39: Video width | O39: 720
B40: Video height | C40: 576 | F40: Video height | G40: 576 | J40: Video height | K40: 576 | N40: Video height | O40: 576
B41: YUV Buf count | C41: 2 | F41: YUV Buf count | G41: 2 | J41: YUV Buf count | K41: 2 | N41: YUV Buf count | O41: 2
...

Sheet Pool Memory
A1: Pool Name | B1: CHIP0/DDR0 | F1: CHIP1/DDR2 | J1: CHIP2/DDR3 | N1: CHIP3/DDR4
B2: Buf Size | C2: Count | D2: Total | F2: Buf Size | G2: Count | H2: Total | J2: Buf Size | K2: Count | L2: Total | N2: Buf Size | O2: Count | P2: Total
A3: HD_COMMON_MEM_COMMON_POOL | B3: =CEILING((D8+D9+D5)*0.1,4) -> 7296 | C3: 1 | D3: =B3*C3 -> 7296 | F3: =CEILING((H8+H9+H5)*0.1,4) -> 23108 | G3: 1 | H3: =F3*G3 -> 23108 | J3: =CEILING((L8+L9+L5)*0.1,4) -> 11556 | K3: 1 | L3: =J3*K3 -> 11556 | N3: =CEILING((P8+P9+P5)*0.1,4) -> 11556 | O3: 1 | P3: =N3*O3 -> 11556
A4: HD_COMMON_MEM_DISP_DEC_IN_POOL | B4: =CEILING(Decode!B16+Decode!B33,4) -> 8492 | C4: 1 | D4: =B4*C4 -> 8492 | F4: 0 | G4: 0 | H4: 0 | J4: 0 | K4: 0 | L4: 0 | N4: 0 | O4: 0 | P4: 0
A5: HD_COMMON_MEM_DISP_DEC_OUT_POOL | B5: =IF(Overview!C7=2,MAX(CEILING(Decode!B17+Decode!B34,4),CEILING(Display!C21,4)),CEILING(Decode!B17+Decode!B34,4)) -> 51008 | C5: 1 | D5: =B5*C5 -> 51008 | F5: =IF(Overview!G7=2,MAX(CEILING(Decode!F17+Decode!F34,4),CEILING(Display!G21,4)),CEILING(Decode!F17+Decode!F34,4)) -> 164096 | G5: 1 | H5: =F5*G5 -> 164096 | J5: =IF(Overview!K7=2,MAX(CEILING(Decode!J17+Decode!J34,4),CEILING(Display!K21,4)),CEILING(Decode!J17+Decode!J34,4)) -> 82048 | K5: 1 | L5: =J5*K5 -> 82048 | N5: =IF(Overview!O7=2,MAX(CEILING(Decode!N17+Decode!N34,4),CEILING(Display!O21,4)),CEILING(Decode!N17+Decode!N34,4)) -> 82048 | O5: 1 | P5: =N5*O5 -> 82048
A6: HD_COMMON_MEM_DISP_DEC_OUT_RATIO_POOL | B6: =CEILING(Decode!B18+Decode!B35,4) -> 12240 | C6: 1 | D6: =B6*C6 -> 12240 | F6: =CEILING(Decode!F18+Decode!F35,4) -> 32640 | G6: 1 | H6: =F6*G6 -> 32640 | J6: =CEILING(Decode!J18+Decode!J35,4) -> 16320 | K6: 1 | L6: =J6*K6 -> 16320 | N6: =CEILING(Decode!N18+Decode!N35,4) -> 16320 | O6: 1 | P6: =N6*O6 -> 16320
A7: HD_COMMON_MEM_DEC_TILE_POOL | B7: =CEILING(MAX(Decode!B15,Decode!B32)*2,4) -> 1836 | C7: 1 | D7: =B7*C7 -> 1836 | F7: =CEILING(MAX(Decode!F15,Decode!F32)*2,4) -> 1836 | G7: 1 | H7: =F7*G7 -> 1836 | J7: =CEILING(MAX(Decode!J15,Decode!J32)*2,4) -> 1836 | K7: 1 | L7: =J7*K7 -> 1836 | N7: =CEILING(MAX(Decode!N15,Decode!N32)*2,4) -> 1836 | O7: 1 | P7: =N7*O7 -> 1836
A8: HD_COMMON_MEM_ENC_CAP_OUT_POOL | B8: =CEILING(Encode!B15+Encode!B34+Encode!B53,4) -> 15936 | C8: 1 | D8: =B8*C8 -> 15936 | F8: =CEILING(Encode!F15+Encode!F34+Encode!F53,4) -> 66976 | G8: 1 | H8: =F8*G8 -> 66976 | J8: =CEILING(Encode!J15+Encode!J34+Encode!J53,4) -> 33488 | K8: 1 | L8: =J8*K8 -> 33488 | N8: =CEILING(Encode!N15+Encode!N34+Encode!N53,4) -> 33488 | O8: 1 | P8: =N8*O8 -> 33488
A9: HD_COMMON_MEM_ENC_OUT_POOL | B9: =CEILING(Encode!B16+Encode!B35+Encode!B54+DispEncode!B16,4) -> 5992 | C9: 1 | D9: =B9*C9 -> 5992 | F9: 0 | G9: 0 | H9: 0 | J9: 0 | K9: 0 | L9: 0 | N9: 0 | O9: 0 | P9: 0
A10: HD_COMMON_MEM_ENC_REF_POOL (Encode 1 REF) | B10: =Encode!B17 -> 3244 | C10: =Encode!B18 -> 6 | D10: =B10*C10 -> 19464 | F10: =Encode!F17 -> 3244 | G10: =Encode!F18 -> 24 | H10: =F10*G10 -> 77856 | J10: =Encode!J17 -> 3244 | K10: =Encode!J18 -> 12 | L10: =J10*K10 -> 38928 | N10: =Encode!N17 -> 3244 | O10: =Encode!N18 -> 12 | P10: =N10*O10 -> 38928
A11: HD_COMMON_MEM_ENC_REF_POOL (Encode 1 TMNR) | B11: =Encode!B19 -> 2328 | C11: =Encode!B20 -> 2 | D11: =B11*C11 -> 4656 | F11: =Encode!F19 -> 3244 | G11: =Encode!F20 -> 8 | H11: =F11*G11 -> 25952 | J11: =Encode!J19 -> 3244 | K11: =Encode!J20 -> 4 | L11: =J11*K11 -> 12976 | N11: =Encode!N19 -> 3244 | O11: =Encode!N20 -> 4 | P11: =N11*O11 -> 12976
A12: HD_COMMON_MEM_ENC_REF_POOL (Encode 2 REF) | B12: =Encode!B36 -> 0 | C12: =Encode!B37 -> 0 | D12: =B12*C12 -> 0 | F12: =Encode!F36 -> 0 | G12: =Encode!F37 -> 0 | H12: =F12*G12 -> 0 | J12: =Encode!J36 -> 0 | K12: =Encode!J37 -> 0 | L12: =J12*K12 -> 0 | N12: =Encode!N36 -> 0 | O12: =Encode!N37 -> 0 | P12: =N12*O12 -> 0
A13: HD_COMMON_MEM_ENC_REF_POOL (Encode 2 TMNR) | B13: =Encode!B38 -> 0 | C13: =Encode!B39 -> 0 | D13: =B13*C13 -> 0 | F13: =Encode!F38 -> 0 | G13: =Encode!F39 -> 0 | H13: =F13*G13 -> 0 | J13: =Encode!J38 -> 0 | K13: =Encode!J39 -> 0 | L13: =J13*K13 -> 0 | N13: =Encode!N38 -> 0 | O13: =Encode!N39 -> 0 | P13: =N13*O13 -> 0
A14: HD_COMMON_MEM_ENC_REF_POOL (Substream REF) | B14: =MAX(Encode!B55,DispEncode!B17) -> 860 | C14: =MAX(Encode!B56,DispEncode!B18) -> 6 | D14: =B14*C14 -> 5160 | F14: =Encode!F55 -> 860 | G14: =Encode!F56 -> 24 | H14: =F14*G14 -> 20640 | J14: =Encode!J55 -> 860 | K14: =Encode!J56 -> 12 | L14: =J14*K14 -> 10320 | N14: =Encode!N55 -> 860 | O14: =Encode!N56 -> 12 | P14: =N14*O14 -> 10320
A15: HD_COMMON_MEM_ENC_REF_POOL (Substream TMNR) | B15: =Encode!B57 -> 616 | C15: =Encode!B58 -> 2 | D15: =B15*C15 -> 1232 | F15: =Encode!F57 -> 860 | G15: =Encode!F58 -> 8 | H15: =F15*G15 -> 6880 | J15: =Encode!J57 -> 860 | K15: =Encode!J58 -> 4 | L15: =J15*K15 -> 3440 | N15: =Encode!N57 -> 860 | O15: =Encode!N58 -> 4 | P15: =N15*O15 -> 3440
A16: HD_COMMON_MEM_ENC_SCL_OUT_POOL | B16: =CEILING(DispEncode!B15+Encode!B68,4) -> 1824 | C16: 1 | D16: =B16*C16 -> 1824 | F16: =CEILING(Encode!F68,4) -> 0 | G16: 1 | H16: =F16*G16 -> 0 | J16: =CEILING(Encode!J68,4) -> 0 | K16: 1 | L16: =J16*K16 -> 0 | N16: =CEILING(Encode!N68,4) -> 0 | O16: 1 | P16: =N16*O16 -> 0
A17: HD_COMMON_MEM_DISP0_CAP_OUT_POOL | B17: =IF(Overview!C7=2,0,CEILING(Display!C21,4)) -> 0 | C17: 1 | D17: =B17*C17 -> 0 | F17: =B17 -> 0 | G17: 1 | H17: =F17*G17 -> 0 | J17: =B17 -> 0 | K17: 1 | L17: =J17*K17 -> 0 | N17: =B17 -> 0 | O17: 1 | P17: =N17*O17 -> 0
A18: HD_COMMON_MEM_DISP0_IN_POOL | B18: =CEILING(Display!C22,4) -> 9180 | C18: 1 | D18: =B18*C18 -> 9180 | F18: 0 | G18: 0 | H18: 0 | J18: 0 | K18: 0 | L18: 0 | N18: 0 | O18: 0 | P18: 0
A19: HD_COMMON_MEM_DISP0_FB_POOL(FB1+FB2+RLE) | B19: =CEILING(Display!C23+Display!C24+Display!C25,4) -> 4092 | C19: 1 | D19: =B19*C19 -> 4092 | F19: 0 | G19: 0 | H19: 0 | J19: 0 | K19: 0 | L19: 0 | N19: 0 | O19: 0 | P19: 0
A20: HD_COMMON_MEM_DISP1_CAP_OUT_POOL | B20: =CEILING(Display!C45,4) -> 1904 | C20: 1 | D20: =B20*C20 -> 1904 | F20: =B20 -> 1904 | G20: 1 | H20: =F20*G20 -> 1904 | J20: =B20 -> 1904 | K20: 1 | L20: =J20*K20 -> 1904 | N20: =B20 -> 1904 | O20: 1 | P20: =N20*O20 -> 1904
A21: HD_COMMON_MEM_DISP1_IN_POOL | B21: =CEILING(Display!C46,4) -> 2432 | C21: 1 | D21: =B21*C21 -> 2432 | F21: 0 | G21: 0 | H21: 0 | J21: 0 | K21: 0 | L21: 0 | N21: 0 | O21: 0 | P21: 0
A22: HD_COMMON_MEM_DISP1_FB_POOL(FB4+FB5) | B22: =CEILING(Display!C47+Display!C48+Display!C49,4) -> 1016 | C22: 1 | D22: =B22*C22 -> 1016 | F22: 0 | G22: 0 | H22: 0 | J22: 0 | K22: 0 | L22: 0 | N22: 0 | O22: 0 | P22: 0
A23: HD_COMMON_MEM_DISP2_CAP_OUT_POOL | B23: =CEILING(Display!C69,4) -> 0 | C23: 1 | D23: =B23*C23 -> 0 | F23: =B23 -> 0 | G23: 1 | H23: =F23*G23 -> 0 | J23: =B23 -> 0 | K23: 1 | L23: =J23*K23 -> 0 | N23: =B23 -> 0 | O23: 1 | P23: =N23*O23 -> 0
A24: HD_COMMON_MEM_DISP2_IN_POOL | B24: =CEILING(Display!C70,4) -> 0 | C24: 1 | D24: =B24*C24 -> 0 | F24: 0 | G24: 0 | H24: 0 | J24: 0 | K24: 0 | L24: 0 | N24: 0 | O24: 0 | P24: 0
A25: HD_COMMON_MEM_DISP2_FB_POOL(FB7+FB8) | B25: =CEILING(Display!C71+Display!C72+Display!C73,4) -> 0 | C25: 1 | D25: =B25*C25 -> 0 | F25: 0 | G25: 0 | H25: 0 | J25: 0 | K25: 0 | L25: 0 | N25: 0 | O25: 0 | P25: 0
A26: HD_COMMON_MEM_AU_ENC_AU_GRAB_OUT_POOL | B26: =CEILING(Audio!B12,4) -> 800 | C26: 1 | D26: =B26*C26 -> 800 | F26: 0 | G26: 0 | H26: 0 | J26: 0 | K26: 0 | L26: 0 | N26: 0 | O26: 0 | P26: 0
A27: HD_COMMON_MEM_AU_DEC_AU_RENDER_IN_POOL | B27: =CEILING(Audio!B22,4) -> 432 | C27: 1 | D27: =B27*C27 -> 432 | F27: 0 | G27: 0 | H27: 0 | J27: 0 | K27: 0 | L27: 0 | N27: 0 | O27: 0 | P27: 0
A28: HD_COMMON_MEM_GLOBAL_MD_POOL | B28: =CEILING(MotionDetection!B9,4) -> 288 | C28: =MotionDetection!B10 -> 2 | D28: =B28*C28 -> 576 | F28: =MotionDetection!F9 -> 288 | G28: =MotionDetection!F10 -> 0 | H28: =F28*G28 -> 0 | J28: =MotionDetection!J9 -> 288 | K28: =MotionDetection!J10 -> 0 | L28: =J28*K28 -> 0 | N28: =MotionDetection!N9 -> 288 | O28: =MotionDetection!N10 -> 0 | P28: =N28*O28 -> 0
A29: HD_COMMON_MEM_TMNR_MOTION_POOL | B29: 140 | C29: =Encode!B4+Encode!B23 -> 2 | D29: =B29*C29 -> 280 | F29: 140 | G29: =Encode!F4+Encode!F23 -> 8 | H29: =F29*G29 -> 1120 | J29: 140 | K29: =Encode!J4+Encode!J23 -> 4 | L29: =J29*K29 -> 560 | N29: 140 | O29: =Encode!N4+Encode!N23 -> 4 | P29: =N29*O29 -> 560
A30: HD_COMMON_MEM_CNN_POOL | B30: 40960 | C30: 1 | D30: =B30*C30 -> 40960 | F30: 40960 | G30: 1 | H30: =F30*G30 -> 40960 | J30: 40960 | K30: 1 | L30: =J30*K30 -> 40960 | N30: 40960 | O30: 1 | P30: =N30*O30 -> 40960
A31: HD_COMMON_MEM_OSG_POOL | B31: 4096 | C31: 1 | D31: =B31*C31 -> 4096 | F31: 4096 | G31: 1 | H31: =F31*G31 -> 4096 | J31: 4096 | K31: 1 | L31: =J31*K31 -> 4096 | N31: 4096 | O31: 1 | P31: =N31*O31 -> 4096
A32: HD_COMMON_MEM_USER_BLK | B32: 32768 | C32: 1 | D32: =B32*C32 -> 32768 | F32: 32768 | G32: 1 | H32: =F32*G32 -> 32768 | J32: 32768 | K32: 1 | L32: =J32*K32 -> 32768 | N32: 32768 | O32: 1 | P32: =N32*O32 -> 32768
A33: HDAL Total Size (KB) | D33: =SUM(D3:D32) -> 233672 | H33: =SUM(H3:H32) -> 500832 | L33: =SUM(L3:L32) -> 291200 | P33: =SUM(P3:P32) -> 291200

Sheet Display
A1: CHIP0
A3: Display 0 | C3: Value | D3: Note
A4: Display Enable | C4: =Overview!C5 -> 1 | F4: Display0(960H) | G4: Value | H4: Note
A5: Video capture input (liveview) | B5: Support | C5: =IF(Overview!C7=0,0,1) -> 1 | F5: De-interlace Support | G5: 1
B6: Total width | C6: =C11 -> 1920 | F6: Resolution width | G6: 960
B7: Height height | C7: =IF(G5=1,CEILING(C12,G7),C12) -> 1152 | F7: Resolution height | G7: 576
B8: YUV buffer count | C8: 4 | F8: Input YUV count | G8: 2
B9: YUV Pixel size (bytes) | C9: 1.5 | F9: Input YUV pixel size | G9: 2
B10: Src Compress ratio | C10: 0.75 | F10: Output YUV count | G10: 2
A11: Video frame buffer (/dev/fb0) | B11: Resolution width | C11: =CEILING(Overview!C8,16) -> 1920 | F11: Output YUV pixel size | G11: 1.5
B12: Resolution height | C12: =CEILING(Overview!C9,16) -> 1088 | F12: Output YUV Compress ratio | G12: =IF(Overview!C2="321",0.75,1) -> 0.75
B13: YUV buffer count | C13: 3 | F13: DISP0_CAP_OUT_POOL | G13: =CEILING((C6*C7*G9*G8+C6*C7*G11*G10*G12)/1024,4)*G5 -> 13500
B14: YUV Pixel size (bytes) | C14: =Overview!C6 -> 1.5
A15: GUI frame buffer (/dev/fb1) | B15: Resolution width | C15: =CEILING(Overview!C10,16) -> 1024
B16: Resolution height | C16: =CEILING(Overview!C11,16) -> 768
B17: YUV Pixel size (bytes) | C17: 2
B18: RLE compress ratio | C18: 0.5
A19: Cursor frame buffer (/dev/fb2) | B19: Support | C19: 1
B20: YUV Pixel size (bytes) | C20: 0.5 | D20: 4bit mode
A21: DISP0_CAP_OUT_POOL(KB) | C21: =MAX(CEILING(((C6*C7*C10*C9+C6*16+C7*16)*C8)/1024,4),G13)*C5*C4 -> 13500
A22: DISP0_IN_POOL/FB0 (KB) | C22: =CEILING((C11*C12*C13*C14)/1024,4)*C4 -> 9180
A23: DISP0_FB1 (KB) | C23: =CEILING(C15*C16*C17/1024,4)*C4 -> 1536
A24: DISP0_FB2 (KB) | C24: =CEILING(C19*C11*C12*C20/1024,4)*C4 -> 1020
A25: DISP0_RLE (KB) | C25: =C23*C18*2*C4 -> 1536 | D25: 2 buffers
A27: Display 1 | C27: Value | D27: Note
A28: Display Enable | C28: =Overview!C12 -> 1 | F28: Display1 (960H) | G28: Value | H28: Note
A29: Video capture input (liveview) | B29: Support | C29: =IF(Overview!C7=0,0,1) -> 1 | F29: De-interlace Support | G29: 0
B30: Total width | C30: =C35 -> 720 | F30: Resolution width | G30: 960
B31: Height height | C31: =IF(G29=1,CEILING(C36,G31),C36) -> 576 | F31: Resolution height | G31: 576
B32: YUV buffer count | C32: 4 | F32: Input YUV count | G32: 2
B33: YUV Pixel size (bytes) | C33: 1.5 | F33: Input YUV pixel size | G33: 2
B34: Src Compress ratio | C34: 0.75 | F34: Output YUV count | G34: 2
A35: Video frame buffer (/dev/fb0) | B35: Resolution width | C35: =CEILING(Overview!C13,16) -> 720 | F35: Output YUV pixel size | G35: 1.5
B36: Resolution height | C36: =CEILING(Overview!C14,16) -> 576 | F36: Output YUV Compress ratio | G36: =IF(Overview!C2="321",0.75,1) -> 0.75
B37: YUV buffer count | C37: 3 | F37: DISP1_CAP_OUT_POOL | G37: =CEILING((C30*C31*G33*G32+C30*C31*G35*G34*G36)/1024,4)*G29 -> 0
B38: YUV Pixel size (bytes) | C38: 2
A39: GUI frame buffer (/dev/fb1) | B39: Resolution width | C39: =CEILING(Overview!C13,16) -> 720
B40: Resolution height | C40: =CEILING(Overview!C14,16) -> 576
B41: YUV Pixel size (bytes) | C41: 2
B42: RLE compress ratio | C42: 0
...

Sheet Encode
A1: CHIP0 | E1: CHIP1 | I1: CHIP2 | M1: CHIP3
A3: Main Encode 1 | B3: Value | C3: Note | E3: Main Encode 1 | F3: Value | G3: Note | I3: Main Encode 1 | J3: Value | K3: Note | M3: Main Encode 1 | N3: Value | O3: Note
A4: Channels | B4: =Overview!C26 -> 2 | E4: Channels | F4: =Overview!G26 -> 8 | I4: Channels | J4: =Overview!K26 -> 4 | M4: Channels | N4: =Overview!O26 -> 4
A5: Resolution width | B5: =CEILING(Overview!C27,16) -> 1920 | E5: Resolution width | F5: =CEILING(Overview!G27,16) -> 1920 | I5: Resolution width | J5: =CEILING(Overview!K27,16) -> 1920 | M5: Resolution width | N5: =CEILING(Overview!O27,16) -> 1920
A6: Resolution height | B6: =CEILING(Overview!C28,16) -> 1088 | E6: Resolution height | F6: =CEILING(Overview!G28,16) -> 1088 | I6: Resolution height | J6: =CEILING(Overview!K28,16) -> 1088 | M6: Resolution height | N6: =CEILING(Overview!O28,16) -> 1088
A7: YUV buffer count | B7: =Overview!C29 -> 2 | E7: YUV buffer count | F7: =B7 -> 2 | I7: YUV buffer count | J7: =B7 -> 2 | M7: YUV buffer count | N7: =B7 -> 2
A8: Max bitrate Kbytes (25fps) | B8: 8192 | E8: Max bitrate Kbytes (25fps) | F8: 8192 | I8: Max bitrate Kbytes (25fps) | J8: 8192 | M8: Max bitrate Kbytes (25fps) | N8: 8192
A9: YUV Pixel size (bytes) | B9: 1.5 | E9: YUV Pixel size (bytes) | F9: 1.5 | I9: YUV Pixel size (bytes) | J9: 1.5 | M9: YUV Pixel size (bytes) | N9: 1.5
A10: Src Compress ratio | B10: 0.75 | E10: Src Compress ratio | F10: 0.75 | I10: Src Compress ratio | J10: 0.75 | M10: Src Compress ratio | N10: 0.75
A11: Min Codec Compress ratio | B11: 0.3 | E11: Min Codec Compress ratio | F11: 0.3 | I11: Min Codec Compress ratio | J11: 0.3 | M11: Min Codec Compress ratio | N11: 0.3
A12: Bitstream buffre count | B12: 7 | E12: Bitstream buffre count | F12: 7 | I12: Bitstream buffre count | J12: 7 | M12: Bitstream buffre count | N12: 7
A13: Reference number | B13: 3 | E13: Reference number | F13: 3 | I13: Reference number | J13: 3 | M13: Reference number | N13: 3
A14: YUV buffer size (enc_cap_out) | B14: =IF(B4>0, CEILING((B5*B6*B9*B10)/1024,4),0) -> 2296 | E14: YUV buffer size (enc_cap_out) | F14: =IF(F4>0, CEILING((F5*F6*F9*F10)/1024,4),0) -> 2296 | I14: YUV buffer size (enc_cap_out) | J14: =IF(J4>0, CEILING((J5*J6*J9*J10)/1024,4),0) -> 2296 | M14: YUV buffer size (enc_cap_out) | N14: =IF(N4>0, CEILING((N5*N6*N9*N10)/1024,4),0) -> 2296
A15: ENC_CAP_OUT_POOL (KB) | B15: =IF(B79*B4*B71>B4*B7*B14,B79*B4,B4*B7*B14) -> 9184 | E15: ENC_CAP_OUT_POOL (KB) | F15: =IF(F79*F4*F71>F4*F7*F14,F79*F4,F4*F7*F14) -> 36736 | I15: ENC_CAP_OUT_POOL (KB) | J15: =IF(J79*J4*J71>J4*J7*J14,J79*J4,J4*J7*J14) -> 18368 | M15: ENC_CAP_OUT_POOL (KB) | N15: =IF(N79*N4*N71>N4*N7*N14,N79*N4,N4*N7*N14) -> 18368
A16: ENC_OUT_POOL (KB) | B16: =CEILING((((B5*B6*B9*B11*2)/1024+(B8/8/25)*B12))*B4,4)+F16+J16+N16 -> 4248 | E16: ENC_OUT_POOL (KB) | F16: =IF(OR(Overview!$C$2="315/316",Overview!$C$2="316x2"),CEILING((((F5*F6*F9*F11*2)/1024+(F8/8/25)*F12))*F4,4),0) -> 0 | I16: ENC_OUT_POOL (KB) | J16: =IF(Overview!$C$2="316x2",CEILING((((J5*J6*J9*J11*2)/1024+(J8/8/25)*J12))*J4,4),0) -> 0 | M16: ENC_OUT_POOL (KB) | N16: =IF(Overview!$C$2="316x2",CEILING((((N5*N6*N9*N11*2)/1024+(N8/8/25)*N12))*N4,4),0) -> 0
A17: Reference Buffer Size (KB) | B17: =IF(B4>0,CEILING((CEILING(B5,64)*CEILING(B6,64)*B9)*1.06/1024, 4),0) -> 3244 | E17: Reference Buffer Size (KB) | F17: =CEILING((CEILING(F5,64)*CEILING(F6,64)*F9)*1.06/1024, 4) -> 3244 | I17: Reference Buffer Size (KB) | J17: =CEILING((CEILING(J5,64)*CEILING(J6,64)*J9)*1.06/1024, 4) -> 3244 | M17: Reference Buffer Size (KB) | N17: =CEILING((CEILING(N5,64)*CEILING(N6,64)*N9)*1.06/1024, 4) -> 3244
A18: Reference Buffer Count | B18: =B4*B13 -> 6 | E18: Reference Buffer Count | F18: =F4*F13 -> 24 | I18: Reference Buffer Count | J18: =J4*J13 -> 12 | M18: Reference Buffer Count | N18: =N4*N13 -> 12
A19: TMNR Buffer Size (KB) | B19: =IF(B4>0,CEILING((CEILING(B5,64)*CEILING(B6,64)*B9)*C19/1024, 4),0) -> 2328 | C19: =IF(Overview!C2="321",0.76,1.06) -> 0.76 | E19: TMNR Buffer Size (KB) | F19: =IF(F4>0,CEILING((CEILING(F5,64)*CEILING(F6,64)*F9)*G19/1024, 4),0) -> 3244 | G19: =IF(Overview!G2="321",0.76,1.06) -> 1.06 | I19: TMNR Buffer Size (KB) | J19: =IF(J4>0,CEILING((CEILING(J5,64)*CEILING(J6,64)*J9)*K19/1024, 4),0) -> 3244 | K19: =IF(Overview!K2="321",0.76,1.06) -> 1.06 | M19: TMNR Buffer Size (KB) | N19: =IF(N4>0,CEILING((CEILING(N5,64)*CEILING(N6,64)*N9)*O19/1024, 4),0) -> 3244 | O19: =IF(Overview!O2="321",0.76,1.06) -> 1.06
A20: TMNR Buffer Count | B20: =B4 -> 2 | E20: TMNR Buffer Count | F20: =F4 -> 8 | I20: TMNR Buffer Count | J20: =J4 -> 4 | M20: TMNR Buffer Count | N20: =N4 -> 4
A22: Main Encode 2 | B22: Value | C22: Note | E22: Main Encode 2 | F22: Value | G22: Note | I22: Main Encode 2 | J22: Value | K22: Note | M22: Main Encode 2 | N22: Value | O22: Note
A23: Channels | B23: =Overview!C30 -> 0 | E23: Channels | F23: =Overview!G30 -> 0 | I23: Channels | J23: =Overview!K30 -> 0 | M23: Channels | N23: =Overview!O30 -> 0
A24: Resolution width | B24: =CEILING(Overview!C31,16) -> 2560 | E24: Resolution width | F24: =CEILING(Overview!G31,16) -> 2560 | I24: Resolution width | J24: =CEILING(Overview!K31,16) -> 2560 | M24: Resolution width | N24: =CEILING(Overview!O31,16) -> 2560
A25: Resolution height | B25: =CEILING(Overview!C32,16) -> 1440 | E25: Resolution height | F25: =CEILING(Overview!G32,16) -> 1440 | I25: Resolution height | J25: =CEILING(Overview!K32,16) -> 1440 | M25: Resolution height | N25: =CEILING(Overview!O32,16) -> 1440
A26: YUV buffer count | B26: =Overview!C33 -> 2 | E26: YUV buffer count | F26: =Overview!G33 -> 2 | I26: YUV buffer count | J26: =Overview!K33 -> 2 | M26: YUV buffer count | N26: =Overview!O33 -> 2
A27: Max bitrate Kbytes (25fps) | B27: 8192 | E27: Max bitrate Kbytes (25fps) | F27: 8192 | I27: Max bitrate Kbytes (25fps) | J27: 8192 | M27: Max bitrate Kbytes (25fps) | N27: 8192
A28: YUV Pixel size (bytes) | B28: 1.5 | E28: YUV Pixel size (bytes) | F28: 1.5 | I28: YUV Pixel size (bytes) | J28: 1.5 | M28: YUV Pixel size (bytes) | N28: 1.5
A29: Src Compress ratio | B29: 0.75 | E29: Src Compress ratio | F29: 0.75 | I29: Src Compress ratio | J29: 0.75 | M29: Src Compress ratio | N29: 0.75
A30: Min Codec Compress ratio | B30: 0.3 | E30: Min Codec Compress ratio | F30: 0.3 | I30: Min Codec Compress ratio | J30: 0.3 | M30: Min Codec Compress ratio | N30: 0.3
A31: Bitstream buffre count | B31: 7 | E31: Bitstream buffre count | F31: 7 | I31: Bitstream buffre count | J31: 7 | M31: Bitstream buffre count | N31: 7
A32: Reference number | B32: 3 | E32: Reference number | F32: 3 | I32: Reference number | J32: 3 | M32: Reference number | N32: 3
A33: YUV buffer size (enc_cap_out) | B33: =IF(B23>0,CEILING((B24*B25*B28*B29)/1024,4),0) -> 0 | E33: YUV buffer size (enc_cap_out) | F33: =IF(F23>0,CEILING((F24*F25*F28*F29)/1024,4),0) -> 0 | I33: YUV buffer size (enc_cap_out) | J33: =IF(J23>0,CEILING((J24*J25*J28*J29)/1024,4),0) -> 0 | M33: YUV buffer size (enc_cap_out) | N33: =IF(N23>0,CEILING((N24*N25*N28*N29)/1024,4),0) -> 0
A34: ENC_CAP_OUT_POOL (KB) | B34: =IF(B71*B79*B23>B23*B26*B33,B79*B23,B23*B26*B33) -> 0 | E34: ENC_CAP_OUT_POOL (KB) | F34: =IF(F71*F79*F23>F23*F26*F33,F79*F23,F23*F26*F33) -> 0 | I34: ENC_CAP_OUT_POOL (KB) | J34: =IF(J71*J79*J23>J23*J26*J33,J79*J23,J23*J26*J33) -> 0 | M34: ENC_CAP_OUT_POOL (KB) | N34: =IF(N71*N79*N23>N23*N26*N33,N79*N23,N23*N26*N33) -> 0
A35: ENC_OUT_POOL (KB) | B35: =CEILING((((B24*B25*B28*B30*2)/1024+(B27/8/25)*B31))*B23,4)+F35+J35+N35 -> 0 | E35: ENC_OUT_POOL (KB) | F35: =IF(OR(Overview!$C$2="315/316",Overview!$C$2="316x2"),CEILING((((F24*F25*F28*F30*2)/1024+(F27/8/25)*F31))*F23,4),0) -> 0 | I35: ENC_OUT_POOL (KB) | J35: =IF(Overview!$C$2="316x2",CEILING((((J24*J25*J28*J30*2)/1024+(J27/8/25)*J31))*J23,4),0) -> 0 | M35: ENC_OUT_POOL (KB) | N35: =IF(Overview!$C$2="316x2",CEILING((((N24*N25*N28*N30*2)/1024+(N27/8/25)*N31))*N23,4),0) -> 0
A36: Reference Buffer Size (KB) | B36: =IF(B23>0,CEILING((CEILING(B24,64)*CEILING(B25,64)*B28)*1.06/1024, 4),0) -> 0 | E36: Reference Buffer Size (KB) | F36: =IF(F23>0,CEILING((CEILING(F24,64)*CEILING(F25,64)*F28)*1.06/1024, 4),0) -> 0 | I36: Reference Buffer Size (KB) | J36: =IF(J23>0,CEILING((CEILING(J24,64)*CEILING(J25,64)*J28)*1.06/1024, 4),0) -> 0 | M36: Reference Buffer Size (KB) | N36: =IF(N23>0,CEILING((CEILING(N24,64)*CEILING(N25,64)*N28)*1.06/1024, 4),0) -> 0
A37: Reference Buffer Count | B37: =B23*B32 -> 0 | E37: Reference Buffer Count | F37: =F23*F32 -> 0 | I37: Reference Buffer Count | J37: =J23*J32 -> 0 | M37: Reference Buffer Count | N37: =N23*N32 -> 0
A38: TMNR Buffer Size (KB) | B38: =IF(B23>0,CEILING((CEILING(B24,64)*CEILING(B25,64)*B28)*C38/1024, 4),0) -> 0 | C38: =IF(Overview!C2="321",0.76,1.06) -> 0.76 | E38: TMNR Buffer Size (KB) | F38: =IF(F23>0,CEILING((CEILING(F24,64)*CEILING(F25,64)*F28)*G38/1024, 4),0) -> 0 | G38: =IF(Overview!G2="321",0.76,1.06) -> 1.06 | I38: TMNR Buffer Size (KB) | J38: =IF(J23>0,CEILING((CEILING(J24,64)*CEILING(J25,64)*J28)*K38/1024, 4),0) -> 0 | K38: =IF(Overview!K2="321",0.76,1.06) -> 1.06 | M38: TMNR Buffer Size (KB) | N38: =IF(N23>0,CEILING((CEILING(N24,64)*CEILING(N25,64)*N28)*O38/1024, 4),0) -> 0 | O38: =IF(Overview!O2="321",0.76,1.06) -> 1.06
A39: TMNR Buffer Count | B39: =B23 -> 0 | E39: TMNR Buffer Count | F39: =F23 -> 0 | I39: TMNR Buffer Count | J39: =J23 -> 0 | M39: TMNR Buffer Count | N39: =N23 -> 0
A41: Sub Encode | B41: Value | C41: Note | E41: Sub Encode | F41: Value | G41: Note | I41: Sub Encode | J41: Value | K41: Note | M41: Sub Encode | N41: Value | O41: Note
A42: Channels | B42: =Overview!C34 -> 2 | E42: Channels | F42: =Overview!G34 -> 8 | I42: Channels | J42: =Overview!K34 -> 4 | M42: Channels | N42: =Overview!O34 -> 4
A43: Resolution width | B43: =CEILING(Overview!C35,16) -> 960 | E43: Resolution width | F43: =CEILING(Overview!G35,16) -> 960 | I43: Resolution width | J43: =CEILING(Overview!K35,16) -> 960 | M43: Resolution width | N43: =CEILING(Overview!O35,16) -> 960
...

Sheet Decode
A1: CHIP0 | E1: CHIP1 | I1: CHIP2 | M1: CHIP3
A3: Decode 1 | B3: Value | C3: Note | E3: Decode 1 | F3: Value | G3: Note | I3: Decode 1 | J3: Value | K3: Note | M3: Decode 1 | N3: Value | O3: Note
A4: Channels | B4: =Overview!C18 -> 4 | E4: Channels | F4: =Overview!G18 -> 8 | I4: Channels | J4: =Overview!K18 -> 4 | M4: Channels | N4: =Overview!O18 -> 4
A5: Resolution width | B5: =CEILING(Overview!C19,16) -> 1920 | E5: Resolution width | F5: =CEILING(Overview!G19,16) -> 1920 | I5: Resolution width | J5: =CEILING(Overview!K19,16) -> 1920 | M5: Resolution width | N5: =CEILING(Overview!O19,16) -> 1920
A6: Resolution height | B6: =CEILING(Overview!C20,16) -> 1088 | E6: Resolution height | F6: =CEILING(Overview!G20,16) -> 1088 | I6: Resolution height | J6: =CEILING(Overview!K20,16) -> 1088 | M6: Resolution height | N6: =CEILING(Overview!O20,16) -> 1088
A7: Max bitrate Kbytes (25fps) | B7: 8192 | E7: Max bitrate Kbytes (25fps) | F7: 8192 | I7: Max bitrate Kbytes (25fps) | J7: 8192 | M7: Max bitrate Kbytes (25fps) | N7: 8192
A8: YUV Pixel size (bytes) | B8: =IF(Overview!C2="321",1.5,2) -> 1.5 | E8: YUV Pixel size (bytes) | F8: 2 | I8: YUV Pixel size (bytes) | J8: 2 | M8: YUV Pixel size (bytes) | N8: 2
A9: Min codec compress Ratio | B9: 0.3 | E9: Min codec compress Ratio | F9: 0.3 | I9: Min codec compress Ratio | J9: 0.3 | M9: Min codec compress Ratio | N9: 0.3
A10: YUV buffer count | B10: =Overview!C21 -> 4 | E10: YUV buffer count | F10: =Overview!G21 -> 4 | I10: YUV buffer count | J10: =Overview!K21 -> 4 | M10: YUV buffer count | N10: =Overview!O21 -> 4
A11: Bitstream buffer count | B11: 7 | E11: Bitstream buffer count | F11: 7 | I11: Bitstream buffer count | J11: 7 | M11: Bitstream buffer count | N11: 7
A12: decode ratio frame | B12: 0.25 | C12: 1/4 yuv | E12: decode ratio frame | F12: 0.25 | G12: 1/4 yuv | I12: decode ratio frame | J12: 0.25 | K12: 1/4 yuv | M12: decode ratio frame | N12: 0.25 | O12: 1/4 yuv
A13: Decode MB info + BS info | B13: =IF(OR(Overview!C2="321",Overview!C2="311/312/313"),C13,CEILING(C13+(B5*B6*1.5*B9)/1024,4)) -> 128 | C13: =CEILING(CEILING(B5,64)*CEILING(B6,64)/16/1024,4) -> 128 | E13: Decode MB info + BS info | F13: =CEILING(C13+(F5*F6*1.5*F9)/1024, 4) -> 1048 | I13: Decode MB info + BS info | J13: =CEILING(C13+(J5*J6*1.5*J9)/1024, 4) -> 1048 | M13: Decode MB info + BS info | N13: =CEILING(C13 + (N5*N6*1.5*N9)/1024, 4) -> 1048
A14: Decode buf size (YUV) | B14: =CEILING((B5*B6*B8)/1024, 4) -> 3060 | E14: Decode buf size (YUV) | F14: =CEILING((F5*F6*F8)/1024, 4) -> 4080 | I14: Decode buf size (YUV) | J14: =CEILING((J5*J6*J8)/1024, 4) -> 4080 | M14: Decode buf size (YUV) | N14: =CEILING((N5*N6*N8)/1024, 4) -> 4080
A15: Max bitstream size | B15: =IF(B4>0,B5*B6*1.5*B9/1024,0) -> 918 | E15: Max bitstream size | F15: =IF(F4>0,F5*F6*1.5*F9/1024,0) -> 918 | I15: Max bitstream size | J15: =IF(J4>0,J5*J6*1.5*J9/1024,0) -> 918 | M15: Max bitstream size | N15: =IF(N4>0,N5*N6*1.5*N9/1024,0) -> 918
A16: DEC_IN_POOL (KB) | B16: =CEILING(((B15*2)+(B7/8/25)*B11)*B4,4)+F16+J16+N16 -> 8492 | E16: DEC_IN_POOL (KB) | F16: =IF(OR(Overview!$C$2="315/316",Overview!$C$2="316x2"),CEILING(((F15*2)+(F7/8/25)*F11)*F4,4),0) -> 0 | G16: CHIP0 | I16: DEC_IN_POOL (KB) | J16: =IF(Overview!$C$2="316x2",CEILING(((J15*2)+(J7/8/25)*J11)*J4,4),0) -> 0 | K16: CHIP0 | M16: DEC_IN_POOL (KB) | N16: =IF(Overview!$C$2="316x2",CEILING(((N15*2)+(N7/8/25)*N11)*N4,4),0) -> 0 | O16: CHIP0
A17: DEC_OUT_POOL (KB) | B17: =CEILING(B14+B13,4)*B4*B10 -> 51008 | E17: DEC_OUT_POOL (KB) | F17: =CEILING(F14+F13,4)*F4*F10 -> 164096 | I17: DEC_OUT_POOL (KB) | J17: =CEILING(J14+J13,4)*J4*J10 -> 82048 | M17: DEC_OUT_POOL (KB) | N17: =CEILING(N14+N13,4)*N4*N10 -> 82048
A18: DEC_OUT_RATIO_POOL (KB) | B18: =CEILING(B14,4)*B4*B10*B12 -> 12240 | E18: DEC_OUT_RATIO_POOL (KB) | F18: =CEILING(F14,4)*F4*F10*F12 -> 32640 | I18: DEC_OUT_RATIO_POOL (KB) | J18: =CEILING(J14,4)*J4*J10*J12 -> 16320 | M18: DEC_OUT_RATIO_POOL (KB) | N18: =CEILING(N14,4)*N4*N10*N12 -> 16320
A20: Decode 2 | B20: Value | C20: Note | E20: Decode 2 | F20: Value | G20: Note | I20: Decode 2 | J20: Value | K20: Note | M20: Decode 2 | N20: Value | O20: Note
A21: Channels | B21: =Overview!C22 -> 0 | E21: Channels | F21: =Overview!G22 -> 0 | I21: Channels | J21: =Overview!K22 -> 0 | M21: Channels | N21: =Overview!O22 -> 0
A22: Resolution width | B22: =Overview!C23 -> 2560 | E22: Resolution width | F22: =Overview!G23 -> 2560 | I22: Resolution width | J22: =Overview!K23 -> 2560 | M22: Resolution width | N22: =Overview!O23 -> 2560
A23: Resolution height | B23: =Overview!C24 -> 1440 | E23: Resolution height | F23: =Overview!G24 -> 1440 | I23: Resolution height | J23: =Overview!K24 -> 1440 | M23: Resolution height | N23: =Overview!O24 -> 1440
A24: Max bitrate Kbytes (25fps) | B24: 8192 | E24: Max bitrate Kbytes (25fps) | F24: 8192 | I24: Max bitrate Kbytes (25fps) | J24: 8192 | M24: Max bitrate Kbytes (25fps) | N24: 8192
A25: YUV Pixel size (bytes) | B25: =IF(Overview!C2="321",1.5,2) -> 1.5 | E25: YUV Pixel size (bytes) | F25: 2 | I25: YUV Pixel size (bytes) | J25: 2 | M25: YUV Pixel size (bytes) | N25: 2
A26: Min codec compress Ratio | B26: 0.3 | E26: Min codec compress Ratio | F26: 0.3 | I26: Min codec compress Ratio | J26: 0.3 | M26: Min codec compress Ratio | N26: 0.3
A27: YUV buffer count | B27: =Overview!C25 -> 4 | E27: YUV buffer count | F27: =Overview!G25 -> 4 | I27: YUV buffer count | J27: =Overview!K25 -> 4 | M27: YUV buffer count | N27: =Overview!O25 -> 4
A28: Bitstream buffer count | B28: 7 | E28: Bitstream buffer count | F28: 7 | I28: Bitstream buffer count | J28: 7 | M28: Bitstream buffer count | N28: 7
A29: decode ratio frame | B29: 0.25 | C29: 1/4 yuv | E29: decode ratio frame | F29: 0.25 | G29: 1/4 yuv | I29: decode ratio frame | J29: 0.25 | K29: 1/4 yuv | M29: decode ratio frame | N29: 0.25 | O29: 1/4 yuv
A30: Decode MB info + BS info | B30: =IF(OR(Overview!C2="321",Overview!C2="311/312/313"),C30,CEILING(C30 + (B22*B23*1.5*B26)/1024, 4)) -> 232 | C30: =CEILING(CEILING(B22,64)*CEILING(B23,64)/16/1024,4) -> 232 | E30: Decode MB info + BS info | F30: =CEILING(C30 + (F22*F23*1.5*F26)/1024, 4) -> 1852 | I30: Decode MB info + BS info | J30: =CEILING(C30 + (J22*J23*1.5*J26)/1024, 4) -> 1852 | M30: Decode MB info + BS info | N30: =CEILING(C30 + (N22*N23*1.5*N26)/1024, 4) -> 1852
A31: Decode buf size (YUV) | B31: =CEILING((B22*B23*B25)/1024, 4) -> 5400 | E31: Decode buf size (YUV) | F31: =CEILING((F22*F23*F25)/1024, 4) -> 7200 | I31: Decode buf size (YUV) | J31: =CEILING((J22*J23*J25)/1024, 4) -> 7200 | M31: Decode buf size (YUV) | N31: =CEILING((N22*N23*N25)/1024, 4) -> 7200
A32: Max bitstream size | B32: =IF(B21>0,B22*B23*1.5*B26/1024,0) -> 0 | E32: Max bitstream size | F32: =IF(F21>0,F22*F23*1.5*F26/1024,0) -> 0 | I32: Max bitstream size | J32: =IF(J21>0,J22*J23*1.5*J26/1024,0) -> 0 | M32: Max bitstream size | N32: =IF(N21>0,N22*N23*1.5*N26/1024,0) -> 0
A33: DEC_IN_POOL (KB) | B33: =CEILING(((B32*2)+(B24/8/25)*B28)*B21,4)+F33+J33+N33 -> 0 | E33: DEC_IN_POOL (KB) | F33: =IF(OR(Overview!$C$2="315/316",Overview!$C$2="316x2"),CEILING(((F32*2)+(F24/8/25)*F28)*F21,4),0) -> 0 | G33: CHIP0 | I33: DEC_IN_POOL (KB) | J33: =IF(Overview!$C$2="316x2",CEILING(((J32*2)+(J24/8/25)*J28)*J21,4),0) -> 0 | K33: CHIP0 | M33: DEC_IN_POOL (KB) | N33: =IF(Overview!$C$2="316x2",CEILING(((N32*2)+(N24/8/25)*N28)*N21,4),0) -> 0 | O33: CHIP0
A34: DEC_OUT_POOL (KB) | B34: =CEILING(B31+B30,4)*B21*B27 -> 0 | E34: DEC_OUT_POOL (KB) | F34: =CEILING(F31+F30,4)*F21*F27 -> 0 | I34: DEC_OUT_POOL (KB) | J34: =CEILING(J31+J30,4)*J21*J27 -> 0 | M34: DEC_OUT_POOL (KB) | N34: =CEILING(N31+N30,4)*N21*N27 -> 0
A35: DEC_OUT_RATIO_POOL (KB) | B35: =CEILING(B31,4)*B21*B27*B29 -> 0 | E35: DEC_OUT_RATIO_POOL (KB) | F35: =CEILING(F31,4)*F21*F27*F29 -> 0 | I35: DEC_OUT_RATIO_POOL (KB) | J35: =CEILING(J31,4)*J21*J27*J29 -> 0 | M35: DEC_OUT_RATIO_POOL (KB) | N35: =CEILING(N31,4)*N21*N27*N29 -> 0

Sheet Audio
A1: CHIP0
A3: Audio Encode | B3: Value | C3: Note
A4: Channels | B4: =Overview!C46 -> 4
A5: Sample rate | B5: =Overview!C47*1000 -> 16000
A6: Tracks | B6: 1
A7: Sample width(bits) | B7: 16
A8: Bitstream buffer time (ms) | B8: 768
A9: Frame samples | B9: 1280
A10: Dual type | B10: 2
A11: Frame buffer count | B11: 20
A12: AU_ENC_AU_GRAB_OUT_POOL (KB) | B12: =CEILING((B9*B6*B7*B4/8)*2*B11*B10/1024,4) -> 800
A14: Audio Decode | B14: Value | C14: Note
A15: Channels | B15: 3
A16: Sample rate | B16: 48000
A17: Tracks | B17: 1
A18: Sample width(bits) | B18: 16
A19: Bitstream buffer time (ms) | B19: 768
A20: Frame samples | B20: 2048
A21: Frame buffer count | B21: 18
A22: AU_DEC_AU_RENDER_IN_POOL (KB) | B22: =CEILING((B20*B17*B18*B15/8)*2*B21/1024,4) -> 432

Sheet DispEncode
A1: CHIP0
A3: Display Encode Parameters | B3: Value | C3: Note
A4: Enable | B4: =IF(Overview!C42="NO",0,1) -> 1
A5: Resolution width | B5: =Overview!C43 -> 720
A6: Resolution height | B6: =Overview!C44 -> 576
A7: YUV buffer count | B7: =Overview!C45 -> 4
A8: Max bitrate | B8: 4096
A9: YUV pixel size (bytes) | B9: 1.5
A10: Src compress ratio | B10: 0.75
A11: Min codec compress ratio | B11: 0.3
A12: Bitstream buffre count | B12: 7
A13: Reference buffer number | B13: 2
A14: YUV buffer size (enc_cap_out) | B14: =CEILING((B5*B6*B9*B10)/1024,4) -> 456
A15: ENC_SCL_OUT_POOL (KB) | B15: =CEILING(B5*B6*B9*B7*B10/1024,4)*B4 -> 1824
A16: ENC_OUT_POOL (KB) | B16: =CEILING((((B5*B6*B9*B11*2)/1024+(B8/8/30)*B12)), 4)*B4 -> 484
A17: Reference Buffer Size (KB) | B17: =CEILING((CEILING(B5,64)*CEILING(B6,64)*B9)*1.06/1024, 4)*B4 -> 688
A18: Reference Buffer Count | B18: =B13*B4 -> 2

Sheet MotionDetection
A1: CHIP0 | E1: CHIP1 | I1: CHIP2 | M1: CHIP3
A3: Motion Detection | B3: Value | C3: Note | E3: Motion Detection | F3: Value | G3: Note | I3: Motion Detection | J3: Value | K3: Note | M3: Motion Detection | N3: Value | O3: Note
A4: Max width | B4: 1920 | E4: Max width | F4: 1920 | I4: Max width | J4: 1920 | M4: Max width | N4: 1920
A5: Max height | B5: 1080 | E5: Max height | F5: 1080 | I5: Max height | J5: 1080 | M5: Max height | N5: 1080
A6: mb_size | B6: =IF(B5<=1088,16,32) -> 16 | E6: mb_size | F6: =IF(F5<=1088,16,32) -> 16 | I6: mb_size | J6: =IF(J5<=1088,16,32) -> 16 | M6: mb_size | N6: =IF(N5<=1088,16,32) -> 16
A7: sta buffer (KB) | B7: =(B4/B6)*(B5/B6)*256/8/1024 -> 253.125 | E7: sta buffer (KB) | F7: =(F4/F6)*(F5/F6)*256/8/1024 -> 253.125 | I7: sta buffer (KB) | J7: =(J4/J6)*(J5/J6)*256/8/1024 -> 253.125 | M7: sta buffer (KB) | N7: =(N4/N6)*(N5/N6)*256/8/1024 -> 253.125
A8: evt buf + level buf | B8: =(256*(B5/B6)*8/8/1024)*2 -> 33.75 | E8: evt buf + level buf | F8: =(256*(F5/F6)*8/8/1024)*2 -> 33.75 | I8: evt buf + level buf | J8: =(256*(J5/J6)*8/8/1024)*2 -> 33.75 | M8: evt buf + level buf | N8: =(256*(N5/N6)*8/8/1024)*2 -> 33.75
A9: MD buffer size (KB) | B9: =CEILING(B7+B8+1,4) -> 288 | C9: 1k header | E9: MD buffer size (KB) | F9: =CEILING(F7+F8+1,4) -> 288 | G9: 1k header | I9: MD buffer size (KB) | J9: =CEILING(J7+J8+1,4) -> 288 | K9: 1k header | M9: MD buffer size (KB) | N9: =CEILING(N7+N8+1,4) -> 288 | O9: 1k header
A10: MD buffer count | B10: =Overview!C26+Overview!C30+F10+J10+N10 -> 2 | E10: MD buffer count | F10: =IF(OR(Overview!$C$2="315/316",Overview!$C$2="316x2"), Overview!G26+Overview!G30,0) -> 0 | I10: MD buffer count | J10: =IF(Overview!$C$2="316x2", Overview!K26+Overview!K30,0) -> 0 | M10: MD buffer count | N10: =IF(Overview!$C$2="316x2", Overview!O26+Overview!O30,0) -> 0
A13: /* * for DVR_4MP_4CH: 4CH 1920x1080 HDMI(1080p)+CVBS * MB_X_NUM_MAX = 256; * MB_Y_NUM_MAX = 256 * MB_GAU_LEN = 256; * EVT_LEN = 8; * LV_LEN = 8; * mb_size = 16; * mb_x_num_max = max_width/mb_size = 2560/32 = 80; * mb_y_num_max = max_height/mb_size = 1440/32 = 45; * sta buf size = mb_x_num_max*mb_y_num_max*MB_GAU_LEN (bits) * = 80*45*256/8 (bytes) * event buf size = MB_X_NUM_MAX*mb_y_num_max*EVT_LEN (bits) * = 256*45*8/8 (bytes) * level buf size = MB_X_NUM_MAX*mb_y_num_max*LV_LEN (bits) * = 256*45*8/8 (bytes) * */

Sheet Video Flow
B2: Liveview | D2: Playback | F2: Encode | H2: Display Encode
B4: videocapture | D4: DISPx_DEC_IN | F4: videocapture | H4: DISPx_IN
B5: ↓ | F5: ↓
B6: DISPx_CAP_OUT | F6: ENC_CAP_OUT
D7: ↓ | H7: ↓
D8: videodec | H8: videoprocess
B9: ↓ | D9: ↓ | F9: ↓ | H9: ↓
B10: videoprocess | D10: DISPx_DEC_OUT | F10: videoenc | H10: ENC_SCL_OUT
B11: ↓ | F11: ↓
B12: DISPx_IN | F12: ENC_OUT
D13: ↓ | H13: ↓
D14: videoprocess | H14: videoenc
B15: ↓ | D15: ↓ | H15: ↓
B16: videoout | D16: DISPx_IN | H16: ENC_OUT
F18: videocapture
D19: ↓ | F19: ↓
D20: videoout | F20: ENC_CAP_OUT
F23: ↓
F24: videoprocess
F25: ↓
F26: ENC_SCL_OUT
F29: ↓
F30: videoenc
F31: ↓
F32: ENC_OUT
